<?xml version='1.0'?>
<sdf version="1.5">
  <model name="agent1">
      <pose>0 0 0 0 0 0</pose>
      <static>false</static>
      
        <link name="base_link">
          <collision name="collision">
            <geometry>
              <box>
                <size>.254 .1524 .04</size>
              </box>
            </geometry>
          </collision>

          <visual name="visual">
            <geometry>
              <box>
                <size>.254 .1524 .04</size>
              </box>
            </geometry>
          </visual>
        </link>

      <link name="lf_wheel_link">
        <pose>.09779 -0.09 -.01079 0 1.5707 1.5707</pose>
          <inertial>
                <mass>0.45</mass>
                <pose>0 0 0 0 0 0</pose>
                <inertia>
                    <ixx>0.00007</ixx>
                    <ixy>0</ixy>
                    <ixz>0</ixz>
                    <iyy>0.00007</iyy>
                    <iyz>0</iyz>
                    <izz>0.000018375</izz>
                </inertia>
          </inertial>
        <collision name="lf_wheel_collision">
          <geometry>
            <cylinder>
              <radius>.02921</radius>
              <length>.0254</length>
            </cylinder>
          </geometry>
          <surface>
            <friction>
                <ode>
                <mu>100000.0</mu>
                <mu2>100000.0</mu2>
                <slip1>0.0</slip1>
                <slip2>0.0</slip2>
                </ode>
            </friction>
          </surface>
        </collision>
        
        <visual name="lf_wheel_visual">
          <geometry>
            <cylinder>
              <radius>.02921</radius>
              <length>.0254</length>
            </cylinder>
          </geometry>
        </visual>
      
      </link>

      <joint type="revolute" name="lf_wheel_joint">
        <pose>0 0 0 -1.5707 0 0</pose>
        <child>lf_wheel_link</child>
        <parent>base_link</parent>
        <axis>
          <xyz>0 1 0</xyz>
        </axis>
      </joint>

      <link name="rf_wheel_link">
        <pose>.09779 0.09 -.01079 0 1.5707 1.5707</pose>
          <inertial>
                <mass>0.45</mass>
                <pose>0 0 0 0 0 0</pose>
                <inertia>
                    <ixx>0.00007</ixx>
                    <ixy>0</ixy>
                    <ixz>0</ixz>
                    <iyy>0.00007</iyy>
                    <iyz>0</iyz>
                    <izz>0.000018375</izz>
                </inertia>
          </inertial>
        <collision name="rf_wheel_collision">
          <geometry>
            <cylinder>
              <radius>.02921</radius>
              <length>.0254</length>
            </cylinder>
          </geometry>
            <surface>
            <friction>
                <ode>
                <mu>100000.0</mu>
                <mu2>100000.0</mu2>
                <slip1>0.0</slip1>
                <slip2>0.0</slip2>
                </ode>
            </friction>
            </surface>
        </collision>

        <visual name="rf_wheel_visual">
          <geometry>
            <cylinder>
              <radius>.02921</radius>
              <length>.0254</length>
            </cylinder>
          </geometry>
        </visual>
      
      </link>

      <joint type="revolute" name="rf_wheel_joint">
        <pose>0 0 0 -1.5707 0 0</pose>
        <child>rf_wheel_link</child>
        <parent>base_link</parent>
        <axis>
          <xyz>0 1 0</xyz>
        </axis>      
      </joint>

      <link name="lb_wheel_link">
        <pose>-.09779 0.09 -.01079 0 1.5707 1.5707</pose>
          <inertial>
                <mass>0.45</mass>
                <pose>0 0 0 0 0 0</pose>
                <inertia>
                    <ixx>0.00007</ixx>
                    <ixy>0</ixy>
                    <ixz>0</ixz>
                    <iyy>0.00007</iyy>
                    <iyz>0</iyz>
                    <izz>0.000018375</izz>
                </inertia>
          </inertial>
        <collision name="lb_wheel_collision">
          <geometry>
            <cylinder>
              <radius>.02921</radius>
              <length>.0254</length>
            </cylinder>
          </geometry>
          <surface>
            <friction>
                <ode>
                <mu>100000.0</mu>
                <mu2>100000.0</mu2>
                <slip1>0.0</slip1>
                <slip2>0.0</slip2>
                </ode>
            </friction>
          </surface>
        </collision>
        
        <visual name="lb_wheel_visual">
          <geometry>
            <cylinder>
              <radius>.02921</radius>
              <length>.0254</length>
            </cylinder>
          </geometry>
        </visual>
        
      </link>

      <joint type="revolute" name="lb_wheel_joint">
        <pose>0 0 0 -1.5707 0 0</pose>
        <child>lb_wheel_link</child>
        <parent>base_link</parent>
        <axis>
          <xyz>0 1 0</xyz>
        </axis>
      </joint>
        
      <link name="rb_wheel_link">
        <pose>-.09779 -0.09 -.01079 0 1.5707 1.5707</pose>
          <inertial>
                <mass>0.45</mass>
                <pose>0 0 0 0 0 0</pose>
                <inertia>
                    <ixx>0.00007</ixx>
                    <ixy>0</ixy>
                    <ixz>0</ixz>
                    <iyy>0.00007</iyy>
                    <iyz>0</iyz>
                    <izz>0.000018375</izz>
                </inertia>
          </inertial>
        <collision name="rb_wheel_collision">
          <geometry>
            <cylinder>
              <radius>.02921</radius>
              <length>.0254</length>
            </cylinder>
          </geometry>
          <surface>
            <friction>
                <ode>
                <mu>100000.0</mu>
                <mu2>100000.0</mu2>
                <slip1>0.0</slip1>
                <slip2>0.0</slip2>
                </ode>
            </friction>
          </surface>
        </collision>
        
        <visual name="rb_wheel_visual">
          <geometry>
            <cylinder>
              <radius>.02921</radius>
              <length>.0254</length>
            </cylinder>
          </geometry>
        </visual>
      </link>

      <joint type="revolute" name="rb_wheel_joint">
        <pose>0 0 0 -1.5707 0 0</pose>
        <child>rb_wheel_link</child>
        <parent>base_link</parent>
        <axis>
          <xyz>0 1 0</xyz>
        </axis>
      </joint>

    <link name = "imu_link">
      <pose> -0.1 0 0.045</pose>
      <visual name = "imu_visual">
        <geometry>
          <box>
            <size> 0.01 0.01 0.01 </size>
          </box>
        </geometry>
      </visual>
      
      <collision name = "imu_collision">
        <geometry>
          <box>
            <size> 0.01 0.01 0.01 </size>
          </box>
        </geometry>
      </collision>

      <sensor name = "imu_sensor" type = "imu">
        <always_on>true</always_on>
        <plugin filename = "libgazebo_ros_imu_sensor.so" name = "imu_plugin">
          <robotNamespace>agent1</robotNamespace>
          <topicName>imu</topicName>
          <updateRateHZ>30</updateRateHZ>
          <frameName>imu_link</frameName>
          <initialOrientationAsReference>false</initialOrientationAsReference>
        </plugin>
      </sensor>
    </link>
    
    <joint name ="imu_joint" type ="fixed">
      <parent>base_link</parent>
      <child>imu_link</child>
    </joint>
    
    <link name = "camera_link">
      <pose>-0.1 0.0 0.03 0 0 0</pose>
      <collision name = "camera_collision">
        <geometry> 
          <box> 
          <size> 0.02 0.09 0.02 </size> 
          </box> 
        </geometry> 
      </collision> 
      
      <visual name = "camera_visual">
        <geometry> 
        	<box> 
          	<size> 0.02 0.09 0.02 </size> 
          </box> 
        </geometry>
      </visual>
      
      <sensor type = "camera" name = "camera">      	
      	<always_on>0</always_on>
        <updateRate>20</updateRate>

        <camera name="camera">
         	<horizontal_fov>0.925024504</horizontal_fov>
          <image>
          	<width>640</width>
            <height>480</height>
          </image>
          <clip>
          	<near>0.5</near>
            <far>25</far>
          </clip>
          <distortion>
            <k1>0.0</k1>
            <k2>0.0</k2>
            <k3>0.0</k3>
            <p1>0.0</p1>
            <p2>0.0</p2>
            <center>0.0 0.0</center>
          </distortion>
        </camera>
        
        <plugin name="camera_controller" filename="libgazebo_ros_camera.so">
        <alwaysOn>true</alwaysOn>
        <updateRate>0.0</updateRate>
        <cameraName>agent1/camera</cameraName>
        <imageTopicName>image</imageTopicName>
        <cameraInfoTopicName>camera_info</cameraInfoTopicName>
        <frameName>camera_link</frameName>
        <hackBaseline>0.07</hackBaseline>
          <distortionK1>0.0</distortionK1>
          <distortionK2>0.0</distortionK2>
          <distortionK3>0.0</distortionK3>
          <distortionT1>0.0</distortionT1>
          <distortionT2>0.0</distortionT2>
        </plugin>

      </sensor>
    </link>

    <joint name="camera_joint" type="fixed">
      <child>camera_link</child>
      <parent>base_link</parent>
    </joint>    

    <plugin name="object_controller" filename="libgazebo_ros_planar_move.so">
        <commandTopic>cmd_vel</commandTopic>
        <odometryTopic>odom</odometryTopic>
        <odometryFrame>odom</odometryFrame>
        <robotBaseFrame>base_link</robotBaseFrame>
        <odometryRate>20.0</odometryRate>  
    </plugin>
  
  </model>
</sdf>
